Workbook

Sheet QCO
A1: QCOSOURCE | B1: RANKING | C1: STYLENAME | D1: BUYERSTYLECODE | E1: BUYERSTYLENAME | F1: STYLECOLORWAYS | G1: QCOFACTORY | H1: QCOYEAR | I1: QCOWEEKNO | J1: QCORANK | K1: CUSTOMRANKING | L1: PRECUSTOMRANK | M1: FACTORY | N1: LINENO | O1: AONO | P1: ADTYPENAME | Q1: BUYER | R1: STYLECODE | S1: STYLESIZE | T1: STYLECOLORSERIAL | U1: REVNO | V1: PRDPKG | W1: MES_SCHEDULING_STATUS | X1: PACKAGEGROUP | Y1: CONFIRMDATE_FACTORY | Z1: CREATEDATE | AA1: NORMALIZEDPERCENT | AB1: QCOSTARTDATE | AC1: CHANGEQCORANK | AD1: REASON | AE1: PRDWEEK | AF1: PREVIOUSCHANGEBY | AG1: PREVIOUSCHANGEQCORANK | AH1: PREVIOUSREASON | AI1: PLANQTY | AJ1: DELIVERYDATE | AK1: PRDSDAT | AL1: PRDEDAT | AM1: ORDQTY | AN1: QCORANKINGNEW | AO1: LATESTQCOTIME | AP1: AOPRDSDAT | AQ1: AOPRDEDAT | AR1: AODELIVERYDATE | AS1: AOPLANQTY | AT1: CHANGEFACTORY | AU1: CHANGEQCORANKSHOW | AV1: QCOVERSION | AW1: MYROWSEQ
A2: QCO | B2: 1 | C2: TIRO TROLLEY XL | D2: S2615GHTT010BA | E2: TIRO TROLLEY XL | F2: JY7982_BLACK/WHITE_FW26 | G2: P3A1 | H2: 2026 | I2: W06 | J2: 423 | K2: 1 | L2: 1454 | M2: P3A1 | N2: LINE10 | O2: AD-ADI-B087 | P2: Main Order | R2: ADIA910 | S2: RGL | T2: 002 | U2: 002 | V2: P_ADI-B087_1_ADIA910RGL002002_03 | W2: Not Scheduled | Y2: 2025/11/15 | Z2: 2026/01/31 | AA2: 90.1 | AE2: 2026-10 | AF2: 22190864 | AG2: 1 | AH2: Week 10 | AI2: 320 | AJ2: 2026/03/07 | AK2: 20260313 | AL2: 20260314 | AM2: 718 | AN2: 3058 | AO2: 46053.81 | AP2: 46094 | AQ2: 46095 | AR2: 2026/03/07 | AS2: 320 | AT2: P3A1 | AU2: 1 | AV2: e519a11ebf634ab69b0a4744a60039a5 | AW2: 1
A3: QCO | B3: 2 | C3: TIRO TROLLEY XL | D3: S2615GHTT010BA | E3: TIRO TROLLEY XL | F3: JY7982_BLACK/WHITE_FW26 | G3: P3A1 | H3: 2026 | I3: W06 | J3: 427 | K3: 2 | L3: 1456 | M3: P3A1 | N3: LINE10 | O3: AD-ADI-B087 | P3: Main Order | R3: ADIA910 | S3: RGL | T3: 002 | U3: 002 | V3: P_ADI-B087_1_ADIA910RGL002002_02 | W3: Not Scheduled | Y3: 2025/11/15 | Z3: 2026/01/31 | AA3: 25.41 | AE3: 2026-10 | AF3: 22190864 | AG3: 2 | AH3: Week 10 | AI3: 383 | AJ3: 2026/03/07 | AK3: 20260311 | AL3: 20260312 | AM3: 718 | AN3: 3062 | AO3: 46053.81 | AP3: 46092 | AQ3: 46093 | AR3: 2026/03/07 | AS3: 383 | AT3: P3A1 | AU3: 2 | AV3: e519a11ebf634ab69b0a4744a60039a5 | AW3: 2
A4: QCO | B4: 3 | C4: TIRO TROLLEY XL | D4: S2615GHTT010BA | E4: TIRO TROLLEY XL | F4: JY7982_BLACK/WHITE_SS27 | G4: P3A1 | H4: 2026 | I4: W06 | J4: 647 | K4: 3 | L4: 1598 | M4: P3A1 | N4: LINE17 | O4: AD-ADI-B179 | P4: Sample Order | R4: ADIA910 | S4: RGL | T4: 003 | U4: 001 | V4: P_ADI-B179_1_ADIA910RGL003001_01 | W4: Not Scheduled | Y4: 2026/01/08 | Z4: 2026/01/31 | AA4: 0 | AE4: 2026-10 | AF4: 22190864 | AG4: 3 | AH4: Week 10 | AI4: 6 | AJ4: 2026/03/12 | AK4: 20260206 | AL4: 20260206 | AM4: 6 | AN4: 3282 | AO4: 46053.813 | AP4: 46059 | AQ4: 46059 | AR4: 2026/03/12 | AS4: 6 | AT4: P3A1 | AU4: 3 | AV4: e519a11ebf634ab69b0a4744a60039a5 | AW4: 3
A5: QCO | B5: 4 | C5: TIRO TROLLEY XL | D5: S2615GHTT010BA | E5: TIRO TROLLEY XL | F5: JY7982_BLACK/WHITE_FW26 | G5: P3A1 | H5: 2026 | I5: W06 | J5: 698 | K5: 4 | L5: 1690 | M5: P3A1 | N5: LINE10 | O5: AD-ADI-B142 | P5: Main Order | R5: ADIA910 | S5: RGL | T5: 002 | U5: 002 | V5: P_ADI-B142_1_ADIA910RGL002002_01 | W5: Not Scheduled | Y5: 2025/12/15 | Z5: 2026/01/31 | AA5: 22.81 | AE5: 2026-10 | AF5: 22190864 | AG5: 4 | AH5: Week 10 | AI5: 482 | AJ5: 2026/03/15 | AK5: 20260310 | AL5: 20260311 | AM5: 482 | AN5: 3333 | AO5: 46053.814 | AP5: 46091 | AQ5: 46092 | AR5: 2026/03/15 | AS5: 482 | AT5: P3A1 | AU5: 4 | AV5: e519a11ebf634ab69b0a4744a60039a5 | AW5: 4
A6: QCO | B6: 5 | C6: TIRO TROLLEY XL | D6: S2615GHTT010BA | E6: TIRO TROLLEY XL | F6: JY7982_BLACK/WHITE_FW26 | G6: P3A1 | H6: 2026 | I6: W06 | J6: 707 | K6: 5 | L6: 1706 | M6: P3A1 | N6: LINE17 | O6: AD-ADI-B195 | P6: Sample Order | R6: ADIA910 | S6: RGL | T6: 002 | U6: 002 | V6: P_ADI-B195_1_ADIA910RGL002002_01 | W6: Not Scheduled | Y6: 2026/01/10 | Z6: 2026/01/31 | AA6: 1.7 | AE6: 2026-10 | AF6: 22190864 | AG6: 5 | AH6: Week 10 | AI6: 1 | AJ6: 2026/03/21 | AK6: 20260302 | AL6: 20260302 | AM6: 1 | AN6: 3342 | AO6: 46053.814 | AP6: 46083 | AQ6: 46083 | AR6: 2026/03/21 | AS6: 1 | AT6: P3A1 | AU6: 5 | AV6: e519a11ebf634ab69b0a4744a60039a5 | AW6: 5
A7: QCO | B7: 6 | C7: TIRO TROLLEY XL | D7: S2615GHTT010BA | E7: TIRO TROLLEY XL | F7: JY7982_BLACK/WHITE_FW26 | G7: P3A1 | H7: 2026 | I7: W06 | J7: 708 | K7: 6 | L7: 1705 | M7: P3A1 | N7: LINE10 | O7: AD-ADI-B192 | P7: Main Order | R7: ADIA910 | S7: RGL | T7: 002 | U7: 002 | V7: P_ADI-B192_1_ADIA910RGL002002_01 | W7: Not Scheduled | Y7: 2026/01/10 | Z7: 2026/01/31 | AA7: 0 | AE7: 2026-10 | AF7: 22190864 | AG7: 6 | AH7: Week 10 | AI7: 2 | AJ7: 2026/03/21 | AK7: 20260313 | AL7: 20260313 | AM7: 2 | AN7: 3343 | AO7: 46053.814 | AP7: 46094 | AQ7: 46094 | AR7: 2026/03/21 | AS7: 2 | AT7: P3A1 | AU7: 6 | AV7: e519a11ebf634ab69b0a4744a60039a5 | AW7: 6
A8: QCO | B8: 7 | C8: TIRO TROLLEY XL | D8: S2615GHTT010BA | E8: TIRO TROLLEY XL | F8: JY7982_BLACK/WHITE_FW26 | G8: P3A1 | H8: 2026 | I8: W06 | J8: 753 | K8: 7 | L8: 1735 | M8: P3A1 | N8: LINE10 | O8: AD-ADI-B154 | P8: Main Order | R8: ADIA910 | S8: RGL | T8: 002 | U8: 002 | V8: P_ADI-B154_1_ADIA910RGL002002_02 | W8: Not Scheduled | Y8: 2025/12/20 | Z8: 2026/01/31 | AA8: 15.75 | AE8: 2026-10 | AF8: 22190864 | AG8: 7 | AH8: Week 10 | AI8: 596 | AJ8: 2026/03/31 | AK8: 20260317 | AL8: 20260319 | AM8: 1096 | AN8: 3388 | AO8: 46053.814 | AP8: 46098 | AQ8: 46100 | AR8: 2026/03/31 | AS8: 596 | AT8: P3A1 | AU8: 7 | AV8: e519a11ebf634ab69b0a4744a60039a5 | AW8: 7
A9: QCO | B9: 8 | C9: TIRO TROLLEY XL | D9: S2615GHTT010BA | E9: TIRO TROLLEY XL | F9: JY7982_BLACK/WHITE_FW26 | G9: P3A1 | H9: 2026 | I9: W06 | J9: 754 | K9: 8 | L9: 1736 | M9: P3A1 | N9: LINE10 | O9: AD-ADI-B154 | P9: Main Order | R9: ADIA910 | S9: RGL | T9: 002 | U9: 002 | V9: P_ADI-B154_1_ADIA910RGL002002_01 | W9: Not Scheduled | Y9: 2025/12/20 | Z9: 2026/01/31 | AA9: 15.75 | AE9: 2026-10 | AF9: 22190864 | AG9: 8 | AH9: Week 10 | AI9: 500 | AJ9: 2026/03/31 | AK9: 20260319 | AL9: 20260320 | AM9: 1096 | AN9: 3389 | AO9: 46053.814 | AP9: 46100 | AQ9: 46101 | AR9: 2026/03/31 | AS9: 500 | AT9: P3A1 | AU9: 8 | AV9: e519a11ebf634ab69b0a4744a60039a5 | AW9: 8
A10: QCO | B10: 9 | C10: TIRO TROLLEY XL | D10: S2615GHTT010BA | E10: TIRO TROLLEY XL | F10: JY7982_BLACK/WHITE_FW26 | G10: P3A1 | H10: 2026 | I10: W06 | J10: 791 | K10: 9 | L10: 1764 | M10: P3A1 | N10: LINE10 | O10: AD-ADI-B143 | P10: Main Order | R10: ADIA910 | S10: RGL | T10: 002 | U10: 002 | V10: P_ADI-B143_1_ADIA910RGL002002_01 | W10: Not Scheduled | Y10: 2025/12/15 | Z10: 2026/01/31 | AA10: 21.63 | AE10: 2026-10 | AF10: 22190864 | AG10: 9 | AH10: Week 10 | AI10: 196 | AJ10: 2026/04/07 | AK10: 20260314 | AL10: 20260314 | AM10: 196 | AN10: 3426 | AO10: 46053.815 | AP10: 46095 | AQ10: 46095 | AR10: 2026/04/07 | AS10: 196 | AT10: P3A1 | AU10: 9 | AV10: e519a11ebf634ab69b0a4744a60039a5 | AW10: 9
A11: QCO | B11: 10 | C11: TIRO TROLLEY XL | D11: S2615GHTT010BA | E11: TIRO TROLLEY XL | F11: JY7982_BLACK/WHITE_FW26 | G11: P3A1 | H11: 2026 | I11: W06 | J11: 857 | K11: 10 | L11: 1813 | M11: P3A1 | N11: LINE10 | O11: AD-ADI-B193 | P11: Main Order | R11: ADIA910 | S11: RGL | T11: 002 | U11: 002 | V11: P_ADI-B193_1_ADIA910RGL002002_01 | W11: Not Scheduled | Y11: 2026/01/10 | Z11: 2026/01/31 | AA11: 0.04 | AE11: 2026-10 | AF11: 22190864 | AG11: 10 | AH11: Week 10 | AI11: 803 | AJ11: 2026/04/15 | AK11: 20260402 | AL11: 20260406 | AM11: 803 | AN11: 3492 | AO11: 46053.816 | AP11: 46114 | AQ11: 46118 | AR11: 2026/04/15 | AS11: 803 | AT11: P3A1 | AU11: 10 | AV11: e519a11ebf634ab69b0a4744a60039a5 | AW11: 10
A12: QCO | B12: 11 | C12: TIRO TROLLEY XL | D12: S2615GHTT010BA | E12: TIRO TROLLEY XL | F12: JY7982_BLACK/WHITE_FW26 | G12: P3A1 | H12: 2026 | I12: W06 | J12: 1069 | K12: 11 | L12: 1981 | M12: P3A1 | N12: 3 | O12: AD-ADI-B208 | P12: Main Order | R12: ADIA910 | S12: RGL | T12: 002 | U12: 002 | V12: P_ADI-B208_1_ADIA910RGL002002_01 | W12: Not Scheduled | Y12: 2026/01/24 | Z12: 2026/01/31 | AA12: 0 | AE12: 2026-10 | AF12: 22190864 | AG12: 11 | AH12: Week 10 | AI12: 77 | AJ12: 2026/04/30 | AK12: 20260302 | AL12: 20260303 | AM12: 77 | AN12: 3704 | AO12: 46053.818 | AP12: 46083 | AQ12: 46084 | AR12: 2026/04/30 | AS12: 77 | AT12: P3A1 | AU12: 11 | AV12: e519a11ebf634ab69b0a4744a60039a5 | AW12: 11
A13: QCO | B13: 12 | C13: TIRO TROLLEY XL | D13: S2615GHTT010BA | E13: TIRO TROLLEY XL | F13: JY7982_BLACK/WHITE_FW26 | G13: P3A1 | H13: 2026 | I13: W06 | J13: 1084 | K13: 12 | L13: 1991 | M13: P3A1 | N13: LINE10 | O13: AD-ADI-B143 | P13: Main Order | R13: ADIA910 | S13: RGL | T13: 002 | U13: 002 | V13: P_ADI-B143_2_ADIA910RGL002002_01 | W13: Not Scheduled | Y13: 2025/12/15 | Z13: 2026/01/31 | AA13: 21.64 | AE13: 2026-10 | AF13: 22190864 | AG13: 12 | AH13: Week 10 | AI13: 630 | AJ13: 2026/05/07 | AK13: 20260406 | AL13: 20260407 | AM13: 630 | AN13: 3719 | AO13: 46053.818 | AP13: 46118 | AQ13: 46119 | AR13: 2026/05/07 | AS13: 630 | AT13: P3A1 | AU13: 12 | AV13: e519a11ebf634ab69b0a4744a60039a5 | AW13: 12
A14: QCO | B14: 13 | C14: TIRO TROLLEY XL | D14: S2615GHTT010BA | E14: TIRO TROLLEY XL | F14: JY7982_BLACK/WHITE_FW26 | G14: P3A1 | H14: 2026 | I14: W06 | J14: 1334 | K14: 13 | L14: 2182 | M14: P3A1 | N14: LINE19 | O14: AD-ADI-B155 | P14: Main Order | R14: ADIA910 | S14: RGL | T14: 002 | U14: 002 | V14: P_ADI-B155_1_ADIA910RGL002002_01 | W14: Not Scheduled | Y14: 2025/12/20 | Z14: 2026/01/31 | AA14: 2.47 | AE14: 2026-10 | AF14: 22190864 | AG14: 13 | AH14: Week 10 | AI14: 153 | AJ14: 2026/06/30 | AK14: 20260506 | AL14: 20260506 | AM14: 153 | AN14: 3969 | AO14: 46053.821 | AP14: 46148 | AQ14: 46148 | AR14: 2026/06/30 | AS14: 153 | AT14: P3A1 | AU14: 13 | AV14: e519a11ebf634ab69b0a4744a60039a5 | AW14: 13
A15: QCO | B15: 14 | C15: TRX TRL VST 10L | D15: S2615BA1307U-M | E15: TRX TRL VST 10L | F15: JY7573-WONDER ALUMINA S25-FW26 | G15: P3A1 | H15: 2026 | I15: W06 | J15: 10 | K15: 14 | L15: 297 | M15: P3A1 | N15: LINE09 | O15: AD-ADI-B051 | P15: Main Order | R15: ADIB295 | S15: RGL | T15: 001 | U15: 003 | V15: P_ADI-B051_1_ADIB295RGL001003_01 | W15: Fully Scheduled | X15: P3A1-2511-000000283 | Y15: 2025/11/05 | Z15: 2026/01/31 | AA15: 96.67 | AE15: 2026-10 | AF15: 22190864 | AG15: 14 | AH15: Week 10 | AI15: 303 | AJ15: 2026/02/15 | AK15: 20260206 | AL15: 20260207 | AM15: 303 | AN15: 2645 | AO15: 46053.773 | AP15: 46059 | AQ15: 46060 | AR15: 2026/02/15 | AS15: 303 | AT15: P3A1 | AU15: 14 | AV15: e519a11ebf634ab69b0a4744a60039a5 | AW15: 14
A16: QCO | B16: 15 | C16: TRX TRL VST 10L | D16: S2615BA1307U-S | E16: TRX TRL VST 10L | F16: JY7573-WONDER ALUMINA S25-FW26 | G16: P3A1 | H16: 2026 | I16: W06 | J16: 11 | K16: 15 | L16: 347 | M16: P3A1 | N16: LINE09 | O16: AD-ADI-B051 | P16: Main Order | R16: ADIB294 | S16: RGL | T16: 001 | U16: 001 | V16: P_ADI-B051_1_ADIB294RGL001001_01 | W16: Fully Scheduled | X16: P3A1-2511-000000285 | Y16: 2025/11/05 | Z16: 2026/01/31 | AA16: 96.67 | AE16: 2026-10 | AF16: 22190864 | AG16: 15 | AH16: Week 10 | AI16: 259 | AJ16: 2026/02/15 | AK16: 20260207 | AL16: 20260207 | AM16: 259 | AN16: 2646 | AO16: 46053.773 | AP16: 46060 | AQ16: 46060 | AR16: 2026/02/15 | AS16: 259 | AT16: P3A1 | AU16: 15 | AV16: e519a11ebf634ab69b0a4744a60039a5 | AW16: 15
A17: QCO | B17: 16 | C17: TRX TRL VST 5L | D17: S2615BA1306U-M | E17: TRX TRL VST 5L | F17: JY7572-TRACE BROWN S17-FW26 | G17: P3A1 | H17: 2026 | I17: W06 | J17: 153 | K17: 16 | L17: 161 | M17: P3A1 | N17: LINE09 | O17: AD-ADI-B117 | P17: Main Order | R17: ADIB291 | S17: RGL | T17: 001 | U17: 002 | V17: P_ADI-B117_1_ADIB291RGL001002_01 | W17: Fully Scheduled | X17: P3A1-2512-000000167 | Y17: 2025/12/01 | Z17: 2026/01/31 | AA17: 94.76 | AE17: 2026-10 | AF17: 22190864 | AG17: 16 | AH17: Week 10 | AI17: 70 | AJ17: 2026/02/28 | AK17: 20260224 | AL17: 20260224 | AM17: 70 | AN17: 2788 | AO17: 46053.775 | AP17: 46077 | AQ17: 46077 | AR17: 2026/02/28 | AS17: 70 | AT17: P3A1 | AU17: 16 | AV17: e519a11ebf634ab69b0a4744a60039a5 | AW17: 16
A18: QCO | B18: 17 | C18: TRX TRL VST 5L | D18: S2615BA1306U-M | E18: TRX TRL VST 5L | F18: KC5015-WONDER ALUMINA S25-FW26 | G18: P3A1 | H18: 2026 | I18: W06 | J18: 168 | K18: 17 | L18: 162 | M18: P3A1 | N18: LINE09 | O18: AD-ADI-B117 | P18: Main Order | R18: ADIB291 | S18: RGL | T18: 002 | U18: 002 | V18: P_ADI-B117_1_ADIB291RGL002002_01 | W18: Fully Scheduled | X18: P3A1-2512-000000178 | Y18: 2025/12/01 | Z18: 2026/01/31 | AA18: 95.1 | AE18: 2026-10 | AF18: 22190864 | AG18: 17 | AH18: Week 10 | AI18: 66 | AJ18: 2026/02/28 | AK18: 20260225 | AL18: 20260225 | AM18: 66 | AN18: 2803 | AO18: 46053.775 | AP18: 46078 | AQ18: 46078 | AR18: 2026/02/28 | AS18: 66 | AT18: P3A1 | AU18: 17 | AV18: e519a11ebf634ab69b0a4744a60039a5 | AW18: 17
A19: QCO | B19: 18 | C19: TRX TRL VST 5L | D19: S2615BA1306U-M | E19: TRX TRL VST 5L | F19: KC5015-WONDER ALUMINA S25-FW26 | G19: P3A1 | H19: 2026 | I19: W06 | J19: 180 | K19: 18 | L19: 164 | M19: P3A1 | N19: LINE09 | O19: AD-ADI-B118 | P19: Main Order | R19: ADIB291 | S19: RGL | T19: 002 | U19: 002 | V19: P_ADI-B118_1_ADIB291RGL002002_02 | W19: Fully Scheduled | X19: P3A1-2512-000000169 | Y19: 2025/12/01 | Z19: 2026/01/31 | AA19: 94.61 | AE19: 2026-10 | AF19: 22190864 | AG19: 18 | AH19: Week 10 | AI19: 180 | AJ19: 2026/03/15 | AK19: 20260225 | AL19: 20260225 | AM19: 508 | AN19: 2815 | AO19: 46053.776 | AP19: 46078 | AQ19: 46078 | AR19: 2026/03/15 | AS19: 180 | AT19: P3A1 | AU19: 18 | AV19: e519a11ebf634ab69b0a4744a60039a5 | AW19: 18
A20: QCO | B20: 19 | C20: TRX TRL VST 10L | D20: S2615BA1307U-M | E20: TRX TRL VST 10L | F20: JY7573-WONDER ALUMINA S25-FW26 | G20: P3A1 | H20: 2026 | I20: W06 | J20: 186 | K20: 19 | L20: 298 | M20: P3A1 | N20: LINE09 | O20: AD-ADI-B054 | P20: Sample Order | R20: ADIB295 | S20: RGL | T20: 001 | U20: 003 | V20: P_ADI-B054_1_ADIB295RGL001003_01 | W20: Fully Scheduled | X20: P3A1-2601-000000100 | Y20: 2025/11/05 | Z20: 2026/01/31 | AA20: 7.4 | AE20: 2026-10 | AF20: 22190864 | AG20: 19 | AH20: Week 10 | AI20: 1 | AJ20: 2026/02/15 | AK20: 20260207 | AL20: 20260207 | AM20: 1 | AN20: 2821 | AO20: 46053.776 | AP20: 46060 | AQ20: 46060 | AR20: 2026/02/15 | AS20: 1 | AT20: P3A1 | AU20: 19 | AV20: e519a11ebf634ab69b0a4744a60039a5 | AW20: 19
A21: QCO | B21: 20 | C21: TRX TRL VST 10L | D21: S2615BA1307U-M | E21: TRX TRL VST 10L | F21: JY7573-WONDER ALUMINA S25-FW26 | G21: P3A1 | H21: 2026 | I21: W06 | J21: 189 | K21: 20 | L21: 299 | M21: P3A1 | N21: LINE09 | O21: AD-ADI-B117 | P21: Main Order | R21: ADIB295 | S21: RGL | T21: 001 | U21: 004 | V21: P_ADI-B117_1_ADIB295RGL001004_01 | W21: Fully Scheduled | X21: P3A1-2601-000000101 | Y21: 2025/12/01 | Z21: 2026/01/31 | AA21: 95.56 | AE21: 2026-10 | AF21: 22190864 | AG21: 20 | AH21: Week 10 | AI21: 8 | AJ21: 2026/02/28 | AK21: 20260207 | AL21: 20260207 | AM21: 8 | AN21: 2824 | AO21: 46053.776 | AP21: 46060 | AQ21: 46060 | AR21: 2026/02/28 | AS21: 8 | AT21: P3A1 | AU21: 20 | AV21: e519a11ebf634ab69b0a4744a60039a5 | AW21: 20
A22: QCO | B22: 21 | C22: TRX TRL VST 10L | D22: S2615BA1307U-L | E22: TRX TRL VST 10L | F22: JY7573-WONDER ALUMINA S25-FW26 | G22: P3A1 | H22: 2026 | I22: W06 | J22: 190 | K22: 21 | L22: 389 | M22: P3A1 | N22: LINE09 | O22: AD-ADI-B117 | P22: Main Order | R22: ADIB296 | S22: RGL | T22: 001 | U22: 003 | V22: P_ADI-B117_1_ADIB296RGL001003_01 | W22: Fully Scheduled | X22: P3A1-2601-000000103 | Y22: 2025/12/01 | Z22: 2026/01/31 | AA22: 95.49 | AE22: 2026-10 | AF22: 22190864 | AG22: 21 | AH22: Week 10 | AI22: 3 | AJ22: 2026/02/28 | AK22: 20260209 | AL22: 20260209 | AM22: 3 | AN22: 2825 | AO22: 46053.776 | AP22: 46062 | AQ22: 46062 | AR22: 2026/02/28 | AS22: 3 | AT22: P3A1 | AU22: 21 | AV22: e519a11ebf634ab69b0a4744a60039a5 | AW22: 21
A23: QCO | B23: 22 | C23: TRX TRL VST 10L | D23: S2615BA1307U-S | E23: TRX TRL VST 10L | F23: JY7573-WONDER ALUMINA S25-FW26 | G23: P3A1 | H23: 2026 | I23: W06 | J23: 191 | K23: 22 | L23: 348 | M23: P3A1 | N23: LINE09 | O23: AD-ADI-B117 | P23: Main Order | R23: ADIB294 | S23: RGL | T23: 001 | U23: 001 | V23: P_ADI-B117_1_ADIB294RGL001001_01 | W23: Fully Scheduled | X23: P3A1-2601-000000098 | Y23: 2025/12/01 | Z23: 2026/01/31 | AA23: 95.22 | AE23: 2026-10 | AF23: 22190864 | AG23: 22 | AH23: Week 10 | AI23: 6 | AJ23: 2026/02/28 | AK23: 20260207 | AL23: 20260207 | AM23: 6 | AN23: 2826 | AO23: 46053.776 | AP23: 46060 | AQ23: 46060 | AR23: 2026/02/28 | AS23: 6 | AT23: P3A1 | AU23: 22 | AV23: e519a11ebf634ab69b0a4744a60039a5 | AW23: 22
A24: QCO | B24: 23 | C24: TRX TRL VST 10L | D24: S2615BA1307U-S | E24: TRX TRL VST 10L | F24: JY7573-WONDER ALUMINA S25-FW26 | G24: P3A1 | H24: 2026 | I24: W06 | J24: 210 | K24: 23 | L24: 349 | M24: P3A1 | N24: LINE09 | O24: AD-ADI-B118 | P24: Main Order | R24: ADIB294 | S24: RGL | T24: 001 | U24: 001 | V24: P_ADI-B118_1_ADIB294RGL001001_01 | W24: Fully Scheduled | X24: P3A1-2601-000000099 | Y24: 2025/12/01 | Z24: 2026/01/31 | AA24: 95.18 | AE24: 2026-10 | AF24: 22190864 | AG24: 23 | AH24: Week 10 | AI24: 141 | AJ24: 2026/03/15 | AK24: 20260207 | AL24: 20260207 | AM24: 141 | AN24: 2845 | AO24: 46053.776 | AP24: 46060 | AQ24: 46060 | AR24: 2026/03/15 | AS24: 141 | AT24: P3A1 | AU24: 23 | AV24: e519a11ebf634ab69b0a4744a60039a5 | AW24: 23
A25: QCO | B25: 24 | C25: TRX TRL VST 10L | D25: S2615BA1307U-L | E25: TRX TRL VST 10L | F25: JY7573-WONDER ALUMINA S25-FW26 | G25: P3A1 | H25: 2026 | I25: W06 | J25: 211 | K25: 24 | L25: 390 | M25: P3A1 | N25: LINE09 | O25: AD-ADI-B118 | P25: Main Order | R25: ADIB296 | S25: RGL | T25: 001 | U25: 003 | V25: P_ADI-B118_1_ADIB296RGL001003_01 | W25: Fully Scheduled | X25: P3A1-2601-000000102 | Y25: 2025/12/01 | Z25: 2026/01/31 | AA25: 95.13 | AE25: 2026-10 | AF25: 22190864 | AG25: 24 | AH25: Week 10 | AI25: 73 | AJ25: 2026/03/15 | AK25: 20260209 | AL25: 20260209 | AM25: 73 | AN25: 2846 | AO25: 46053.776 | AP25: 46062 | AQ25: 46062 | AR25: 2026/03/15 | AS25: 73 | AT25: P3A1 | AU25: 24 | AV25: e519a11ebf634ab69b0a4744a60039a5 | AW25: 24
A26: QCO | B26: 25 | C26: TRX TRL VST 10L | D26: S2615BA1307U-M | E26: TRX TRL VST 10L | F26: JY7573-WONDER ALUMINA S25-FW26 | G26: P3A1 | H26: 2026 | I26: W06 | J26: 213 | K26: 25 | L26: 300 | M26: P3A1 | N26: LINE09 | O26: AD-ADI-B118 | P26: Main Order | R26: ADIB295 | S26: RGL | T26: 001 | U26: 004 | V26: P_ADI-B118_1_ADIB295RGL001004_01 | W26: Fully Scheduled | X26: P3A1-2601-000000097 | Y26: 2025/12/01 | Z26: 2026/01/31 | AA26: 94.93 | AE26: 2026-10 | AF26: 22190864 | AG26: 25 | AH26: Week 10 | AI26: 181 | AJ26: 2026/03/15 | AK26: 20260207 | AL26: 20260207 | AM26: 181 | AN26: 2848 | AO26: 46053.776 | AP26: 46060 | AQ26: 46060 | AR26: 2026/03/15 | AS26: 181 | AT26: P3A1 | AU26: 25 | AV26: e519a11ebf634ab69b0a4744a60039a5 | AW26: 25
... A28: QCO | B28: 27 | C28: TRX TRL VST 5L | D28: S2615BA1306U-M | E28: TRX TRL VST 5L | F28: KC5015-WONDER ALUMINA S25-FW26 | G28: P3A1 | H28: 2026 | I28: W06 | J28: 226 | K28: 27 | L28: 167 | M28: P3A1 | N28: LINE09 | O28: AD-ADI-B118 | P28: Main Order | R28: ADIB291 | S28: RGL | T28: 002 | U28: 002 | V28: P_ADI-B118_2_ADIB291RGL002002_01 | W28: Fully Scheduled | X28: P3A1-2512-000000175 | Y28: 2025/12/01 | Z28: 2026/01/31 | AA28: 94.56 | AE28: 2026-10 | AF28: 22190864 | AG28: 27 | AH28: Week 10 | AI28: 68 | AJ28: 2026/04/15 | AK28: 20260225 | AL28: 20260225 | AM28: 68 | AN28: 2861 | AO28: 46053.776 | AP28: 46078 | AQ28: 46078 | AR28: 2026/04/15 | AS28: 68 | AT28: P3A1 | AU28: 27 | AV28: e519a11ebf634ab69b0a4744a60039a5 | AW28: 27
A29: QCO | B29: 28 | C29: TRX TRL VST 10L | D29: S2615BA1307U-M | E29: TRX TRL VST 10L | F29: JY7573-WONDER ALUMINA S25-FW26 | G29: P3A1 | H29: 2026 | I29: W06 | J29: 722 | K29: 28 | L29: 301 | M29: P3A1 | N29: LINE09 | O29: AD-ADI-B142 | P29: Main Order | R29: ADIB295 | S29: RGL | T29: 001 | U29: 004 | V29: P_ADI-B142_1_ADIB295RGL001004_01 | W29: Not Scheduled | Y29: 2025/12/15 | Z29: 2026/01/31 | AA29: 88.99 | AE29: 2026-10 | AF29: 22190864 | AG29: 28 | AH29: Week 10 | AI29: 71 | AJ29: 2026/03/31 | AK29: 20260313 | AL29: 20260313 | AM29: 71 | AN29: 3357 | AO29: 46053.814 | AP29: 46094 | AQ29: 46094 | AR29: 2026/03/31 | AS29: 71 | AT29: P3A1 | AU29: 28 | AV29: e519a11ebf634ab69b0a4744a60039a5 | AW29: 28
A30: QCO | B30: 29 | C30: TRX TRL VST 10L | D30: S2615BA1307U-S | E30: TRX TRL VST 10L | F30: JY7573-WONDER ALUMINA S25-FW26 | G30: P3A1 | H30: 2026 | I30: W06 | J30: 725 | K30: 29 | L30: 350 | M30: P3A1 | N30: LINE09 | O30: AD-ADI-B142 | P30: Main Order | R30: ADIB294 | S30: RGL | T30: 001 | U30: 001 | V30: P_ADI-B142_1_ADIB294RGL001001_01 | W30: Not Scheduled | Y30: 2025/12/15 | Z30: 2026/01/31 | AA30: 88.33 | AE30: 2026-10 | AF30: 22190864 | AG30: 29 | AH30: Week 10 | AI30: 10 | AJ30: 2026/03/31 | AK30: 20260313 | AL30: 20260313 | AM30: 10 | AN30: 3360 | AO30: 46053.814 | AP30: 46094 | AQ30: 46094 | AR30: 2026/03/31 | AS30: 10 | AT30: P3A1 | AU30: 29 | AV30: e519a11ebf634ab69b0a4744a60039a5 | AW30: 29
A31: QCO | B31: 30 | C31: TRX TRL VST 5L | D31: S2615BA1306U-M | E31: TRX TRL VST 5L | F31: KC5015-WONDER ALUMINA S25-FW26 | G31: P3A1 | H31: 2026 | I31: W06 | J31: 729 | K31: 30 | L31: 168 | M31: P3A1 | N31: LINE09 | O31: AD-ADI-B142 | P31: Main Order | R31: ADIB291 | S31: RGL | T31: 002 | U31: 002 | V31: P_ADI-B142_1_ADIB291RGL002002_01 | W31: Not Scheduled | Y31: 2025/12/15 | Z31: 2026/01/31 | AA31: 87.13 | AE31: 2026-10 | AF31: 22190864 | AG31: 30 | AH31: Week 10 | AI31: 264 | AJ31: 2026/03/31 | AK31: 20260313 | AL31: 20260314 | AM31: 264 | AN31: 3364 | AO31: 46053.814 | AP31: 46094 | AQ31: 46095 | AR31: 2026/03/31 | AS31: 264 | AT31: P3A1 | AU31: 30 | AV31: e519a11ebf634ab69b0a4744a60039a5 | AW31: 30
A32: QCO | B32: 31 | C32: TRX TRL VST 10L | D32: S2615BA1307U-L | E32: TRX TRL VST 10L | F32: JY7573-WONDER ALUMINA S25-FW26 | G32: P3A1 | H32: 2026 | I32: W06 | J32: 749 | K32: 31 | L32: 391 | M32: P3A1 | N32: LINE09 | O32: AD-ADI-B142 | P32: Main Order | R32: ADIB296 | S32: RGL | T32: 001 | U32: 003 | V32: P_ADI-B142_1_ADIB296RGL001003_01 | W32: Not Scheduled | Y32: 2025/12/15 | Z32: 2026/01/31 | AA32: 28.15 | AE32: 2026-10 | AF32: 22190864 | AG32: 31 | AH32: Week 10 | AI32: 56 | AJ32: 2026/03/31 | AK32: 20260313 | AL32: 20260313 | AM32: 56 | AN32: 3384 | AO32: 46053.814 | AP32: 46094 | AQ32: 46094 | AR32: 2026/03/31 | AS32: 56 | AT32: P3A1 | AU32: 31 | AV32: e519a11ebf634ab69b0a4744a60039a5 | AW32: 31
A33: QCO | B33: 32 | C33: TRX TRL VST 5L | D33: S2615BA1306U-M | E33: TRX TRL VST 5L | F33: KC5015-WONDER ALUMINA S25-FW26 | G33: P3A1 | H33: 2026 | I33: W06 | J33: 822 | K33: 32 | L33: 171 | M33: P3A1 | N33: LINE09 | O33: AD-ADI-B143 | P33: Main Order | R33: ADIB291 | S33: RGL | T33: 002 | U33: 002 | V33: P_ADI-B143_1_ADIB291RGL002002_01 | W33: Not Scheduled | Y33: 2025/12/15 | Z33: 2026/01/31 | AA33: 23.04 | AE33: 2026-10 | AF33: 22190864 | AG33: 32 | AH33: Week 10 | AI33: 43 | AJ33: 2026/04/15 | AK33: 20260314 | AL33: 20260314 | AM33: 43 | AN33: 3457 | AO33: 46053.815 | AP33: 46095 | AQ33: 46095 | AR33: 2026/04/15 | AS33: 43 | AT33: P3A1 | AU33: 32 | AV33: e519a11ebf634ab69b0a4744a60039a5 | AW33: 32
A34: QCO | B34: 33 | C34: TRX TRL VST 10L | D34: S2615BA1307U-S | E34: TRX TRL VST 10L | F34: JY7573-WONDER ALUMINA S25-FW26 | G34: P3A1 | H34: 2026 | I34: W06 | J34: 837 | K34: 33 | L34: 351 | M34: P3A1 | N34: LINE09 | O34: AD-ADI-B154 | P34: Main Order | R34: ADIB294 | S34: RGL | T34: 001 | U34: 001 | V34: P_ADI-B154_1_ADIB294RGL001001_01 | W34: Not Scheduled | Y34: 2025/12/20 | Z34: 2026/01/31 | AA34: 1.71 | AE34: 2026-10 | AF34: 22190864 | AG34: 33 | AH34: Week 10 | AI34: 33 | AJ34: 2026/04/15 | AK34: 20260314 | AL34: 20260314 | AM34: 33 | AN34: 3472 | AO34: 46053.815 | AP34: 46095 | AQ34: 46095 | AR34: 2026/04/15 | AS34: 33 | AT34: P3A1 | AU34: 33 | AV34: e519a11ebf634ab69b0a4744a60039a5 | AW34: 33
A35: QCO | B35: 34 | C35: TRX TRL VST 10L | D35: S2615BA1307U-M | E35: TRX TRL VST 10L | F35: JY7573-WONDER ALUMINA S25-FW26 | G35: P3A1 | H35: 2026 | I35: W06 | J35: 839 | K35: 34 | L35: 302 | M35: P3A1 | N35: LINE09 | O35: AD-ADI-B154 | P35: Main Order | R35: ADIB295 | S35: RGL | T35: 001 | U35: 004 | V35: P_ADI-B154_1_ADIB295RGL001004_01 | W35: Not Scheduled | Y35: 2025/12/20 | Z35: 2026/01/31 | AA35: 1.64 | AE35: 2026-10 | AF35: 22190864 | AG35: 34 | AH35: Week 10 | AI35: 32 | AJ35: 2026/04/15 | AK35: 20260314 | AL35: 20260314 | AM35: 32 | AN35: 3474 | AO35: 46053.815 | AP35: 46095 | AQ35: 46095 | AR35: 2026/04/15 | AS35: 32 | AT35: P3A1 | AU35: 34 | AV35: e519a11ebf634ab69b0a4744a60039a5 | AW35: 34
A36: QCO | B36: 35 | C36: TRX TRL VST 10L | D36: S2615BA1307U-L | E36: TRX TRL VST 10L | F36: JY7573-WONDER ALUMINA S25-FW26 | G36: P3A1 | H36: 2026 | I36: W06 | J36: 842 | K36: 35 | L36: 392 | M36: P3A1 | N36: LINE09 | O36: AD-ADI-B154 | P36: Main Order | R36: ADIB296 | S36: RGL | T36: 001 | U36: 003 | V36: P_ADI-B154_1_ADIB296RGL001003_01 | W36: Not Scheduled | Y36: 2025/12/20 | Z36: 2026/01/31 | AA36: 1.52 | AE36: 2026-10 | AF36: 22190864 | AG36: 35 | AH36: Week 10 | AI36: 17 | AJ36: 2026/04/15 | AK36: 20260314 | AL36: 20260314 | AM36: 17 | AN36: 3477 | AO36: 46053.815 | AP36: 46095 | AQ36: 46095 | AR36: 2026/04/15 | AS36: 17 | AT36: P3A1 | AU36: 35 | AV36: e519a11ebf634ab69b0a4744a60039a5 | AW36: 35
A37: QCO | B37: 36 | C37: TRX TRL VST 5L | D37: S2615BA1306U-M | E37: TRX TRL VST 5L | F37: KC5015-WONDER ALUMINA S25-FW26 | G37: P3A1 | H37: 2026 | I37: W06 | J37: 904 | K37: 36 | L37: 172 | M37: P3A1 | N37: 3 | O37: AD-ADI-B208 | P37: Main Order | R37: ADIB291 | S37: RGL | T37: 002 | U37: 002 | V37: P_ADI-B208_1_ADIB291RGL002002_01 | W37: Not Scheduled | Y37: 2026/01/24 | Z37: 2026/01/31 | AA37: 0 | AE37: 2026-10 | AF37: 22190864 | AG37: 36 | AH37: Week 10 | AI37: 2 | AJ37: 2026/04/20 | AK37: 20260302 | AL37: 20260303 | AM37: 2 | AN37: 3539 | AO37: 46053.816 | AP37: 46083 | AQ37: 46084 | AR37: 2026/04/20 | AS37: 2 | AT37: P3A1 | AU37: 36 | AV37: e519a11ebf634ab69b0a4744a60039a5 | AW37: 36
A38: QCO | B38: 37 | C38: TRX TRL VST 5L | D38: S2615BA1306U-M | E38: TRX TRL VST 5L | F38: KC5015-WONDER ALUMINA S25-FW26 | G38: P3A1 | H38: 2026 | I38: W06 | J38: 910 | K38: 37 | L38: 173 | M38: P3A1 | N38: LINE17 | O38: AD-ADI-B211 | P38: Sample Order | R38: ADIB291 | S38: RGL | T38: 002 | U38: 002 | V38: P_ADI-B211_1_ADIB291RGL002002_01 | W38: Not Scheduled | Y38: 2026/01/24 | Z38: 2026/01/31 | AA38: 0 | AE38: 2026-10 | AF38: 22190864 | AG38: 37 | AH38: Week 10 | AI38: 1 | AJ38: 2026/04/20 | AK38: 20260225 | AL38: 20260225 | AM38: 1 | AN38: 3545 | AO38: 46053.816 | AP38: 46078 | AQ38: 46078 | AR38: 2026/04/20 | AS38: 1 | AT38: P3A1 | AU38: 37 | AV38: e519a11ebf634ab69b0a4744a60039a5 | AW38: 37
A39: QCO | B39: 38 | C39: TRX TRL VST 5L | D39: S2615BA1306U-M | E39: TRX TRL VST 5L | F39: JY7572-TRACE BROWN S17-FW26 | G39: P3A1 | H39: 2026 | I39: W06 | J39: 1056 | K39: 38 | L39: 175 | M39: P3A1 | N39: LINE09 | O39: AD-ADI-B193 | P39: Main Order | R39: ADIB291 | S39: RGL | T39: 001 | U39: 002 | V39: P_ADI-B193_1_ADIB291RGL001002_01 | W39: Not Scheduled | Y39: 2026/01/10 | Z39: 2026/01/31 | AA39: 0 | AE39: 2026-10 | AF39: 22190864 | AG39: 38 | AH39: Week 10 | AI39: 278 | AJ39: 2026/04/30 | AK39: 20260411 | AL39: 20260411 | AM39: 278 | AN39: 3691 | AO39: 46053.818 | AP39: 46123 | AQ39: 46123 | AR39: 2026/04/30 | AS39: 278 | AT39: P3A1 | AU39: 38 | AV39: e519a11ebf634ab69b0a4744a60039a5 | AW39: 38
A40: QCO | B40: 39 | C40: TRX TRL VST 10L | D40: S2615BA1307U-L | E40: TRX TRL VST 10L | F40: JY7573-WONDER ALUMINA S25-FW26 | G40: P3A1 | H40: 2026 | I40: W06 | J40: 1060 | K40: 39 | L40: 393 | M40: P3A1 | N40: LINE09 | O40: AD-ADI-B193 | P40: Main Order | R40: ADIB296 | S40: RGL | T40: 001 | U40: 003 | V40: P_ADI-B193_1_ADIB296RGL001003_01 | W40: Not Scheduled | Y40: 2026/01/10 | Z40: 2026/01/31 | AA40: 0 | AE40: 2026-10 | AF40: 22190864 | AG40: 39 | AH40: Week 10 | AI40: 193 | AJ40: 2026/04/30 | AK40: 20260408 | AL40: 20260408 | AM40: 193 | AN40: 3695 | AO40: 46053.818 | AP40: 46120 | AQ40: 46120 | AR40: 2026/04/30 | AS40: 193 | AT40: P3A1 | AU40: 39 | AV40: e519a11ebf634ab69b0a4744a60039a5 | AW40: 39
... A48: QCO | B48: 47 | C48: TRX TRL VST 5L | D48: S2615BA1306U-M | E48: TRX TRL VST 5L | F48: KC5015-WONDER ALUMINA S25-FW26 | G48: P3A1 | H48: 2026 | I48: W06 | J48: 1392 | K48: 47 | L48: 180 | M48: P3A1 | N48: 2 | O48: AD-ADI-B210 | P48: Main Order | R48: ADIB291 | S48: RGL | T48: 002 | U48: 002 | V48: P_ADI-B210_1_ADIB291RGL002002_01 | W48: Not Scheduled | Y48: 2026/01/24 | Z48: 2026/01/31 | AA48: 0 | AE48: 2026-10 | AF48: 22190864 | AG48: 47 | AH48: Week 10 | AI48: 139 | AJ48: 2026/08/07 | AK48: 20260318 | AL48: 20260319 | AM48: 139 | AN48: 4027 | AO48: 46053.822 | AP48: 46099 | AQ48: 46100 | AR48: 2026/08/07 | AS48: 139 | AT48: P3A1 | AU48: 47 | AV48: e519a11ebf634ab69b0a4744a60039a5 | AW48: 47
...

Sheet Sheet1
A1: QCOSOURCE | B1: RANKING | C1: STYLENAME | D1: BUYERSTYLECODE | E1: BUYERSTYLENAME | F1: STYLECOLORWAYS | G1: QCOFACTORY | H1: QCOYEAR | I1: QCOWEEKNO | J1: QCORANK | K1: CUSTOMRANKING | L1: PRECUSTOMRANK | M1: FACTORY | N1: LINENO | O1: AONO | P1: ADTYPENAME | Q1: BUYER | R1: STYLECODE | S1: STYLESIZE | T1: STYLECOLORSERIAL | U1: REVNO | V1: PRDPKG | W1: MES_SCHEDULING_STATUS | X1: PACKAGEGROUP | Y1: CONFIRMDATE_FACTORY | Z1: CREATEDATE | AA1: NORMALIZEDPERCENT | AB1: QCOSTARTDATE | AC1: CHANGEQCORANK | AD1: REASON | AE1: PRDWEEK | AF1: PREVIOUSCHANGEBY | AG1: PREVIOUSCHANGEQCORANK | AH1: PREVIOUSREASON | AI1: PLANQTY | AJ1: DELIVERYDATE | AK1: PRDSDAT | AL1: PRDEDAT | AM1: ORDQTY | AN1: QCORANKINGNEW | AO1: LATESTQCOTIME | AP1: AOPRDSDAT | AQ1: AOPRDEDAT | AR1: AODELIVERYDATE | AS1: AOPLANQTY | AT1: CHANGEFACTORY | AU1: CHANGEQCORANKSHOW | AV1: QCOVERSION | AW1: MYROWSEQ
A2: QCO | B2: 16 | C2: TRX TRL VST 5L | D2: S2615BA1306U-M | E2: TRX TRL VST 5L | F2: JY7572-TRACE BROWN S17-FW26 | G2: P3A1 | H2: 2026 | I2: W06 | J2: 153 | K2: 16 | L2: 161 | M2: P3A1 | N2: LINE09 | O2: AD-ADI-B117 | P2: Main Order | R2: ADIB291 | S2: RGL | T2: 001 | U2: 002 | V2: P_ADI-B117_1_ADIB291RGL001002_01 | W2: Fully Scheduled | X2: P3A1-2512-000000167 | Y2: 2025/12/01 | Z2: 2026/01/31 | AA2: 94.76 | AB2: 20260319 | AC2: 130 | AD2: Week 11 | AE2: 2026-11 | AF2: 22190864 | AG2: 16 | AH2: Week 10 | AI2: 70 | AJ2: 2026/02/28 | AK2: 20260224 | AL2: 20260224 | AM2: 70 | AN2: 2788 | AO2: 46053.775 | AP2: 46077 | AQ2: 46077 | AR2: 2026/02/28 | AS2: 70 | AT2: P3A1 | AU2: 16 | AV2: e519a11ebf634ab69b0a4744a60039a5 | AW2: 16
A3: QCO | B3: 17 | C3: TRX TRL VST 5L | D3: S2615BA1306U-M | E3: TRX TRL VST 5L | F3: KC5015-WONDER ALUMINA S25-FW26 | G3: P3A1 | H3: 2026 | I3: W06 | J3: 168 | K3: 17 | L3: 162 | M3: P3A1 | N3: LINE09 | O3: AD-ADI-B117 | P3: Main Order | R3: ADIB291 | S3: RGL | T3: 002 | U3: 002 | V3: P_ADI-B117_1_ADIB291RGL002002_01 | W3: Fully Scheduled | X3: P3A1-2512-000000178 | Y3: 2025/12/01 | Z3: 2026/01/31 | AA3: 95.1 | AB3: 20260319 | AC3: 131 | AD3: Week 11 | AE3: 2026-11 | AF3: 22190864 | AG3: 17 | AH3: Week 10 | AI3: 66 | AJ3: 2026/02/28 | AK3: 20260225 | AL3: 20260225 | AM3: 66 | AN3: 2803 | AO3: 46053.775 | AP3: 46078 | AQ3: 46078 | AR3: 2026/02/28 | AS3: 66 | AT3: P3A1 | AU3: 17 | AV3: e519a11ebf634ab69b0a4744a60039a5 | AW3: 17
A4: QCO | B4: 18 | C4: TRX TRL VST 5L | D4: S2615BA1306U-M | E4: TRX TRL VST 5L | F4: KC5015-WONDER ALUMINA S25-FW26 | G4: P3A1 | H4: 2026 | I4: W06 | J4: 180 | K4: 18 | L4: 164 | M4: P3A1 | N4: LINE09 | O4: AD-ADI-B118 | P4: Main Order | R4: ADIB291 | S4: RGL | T4: 002 | U4: 002 | V4: P_ADI-B118_1_ADIB291RGL002002_02 | W4: Fully Scheduled | X4: P3A1-2512-000000169 | Y4: 2025/12/01 | Z4: 2026/01/31 | AA4: 94.61 | AB4: 20260319 | AC4: 132 | AD4: Week 11 | AE4: 2026-11 | AF4: 22190864 | AG4: 18 | AH4: Week 10 | AI4: 180 | AJ4: 2026/03/15 | AK4: 20260225 | AL4: 20260225 | AM4: 508 | AN4: 2815 | AO4: 46053.776 | AP4: 46078 | AQ4: 46078 | AR4: 2026/03/15 | AS4: 180 | AT4: P3A1 | AU4: 18 | AV4: e519a11ebf634ab69b0a4744a60039a5 | AW4: 18
A5: QCO | B5: 26 | C5: TRX TRL VST 5L | D5: S2615BA1306U-M | E5: TRX TRL VST 5L | F5: KC5015-WONDER ALUMINA S25-FW26 | G5: P3A1 | H5: 2026 | I5: W06 | J5: 215 | K5: 26 | L5: 166 | M5: P3A1 | N5: LINE09 | O5: AD-ADI-B118 | P5: Main Order | R5: ADIB291 | S5: RGL | T5: 002 | U5: 002 | V5: P_ADI-B118_1_ADIB291RGL002002_01 | W5: Fully Scheduled | X5: P3A1-2512-000000181 | Y5: 2025/12/01 | Z5: 2026/01/31 | AA5: 94.59 | AB5: 20260319 | AC5: 133 | AD5: Week 11 | AE5: 2026-11 | AF5: 22190864 | AG5: 26 | AH5: Week 10 | AI5: 328 | AJ5: 2026/03/15 | AK5: 20260225 | AL5: 20260226 | AM5: 508 | AN5: 2850 | AO5: 46053.776 | AP5: 46078 | AQ5: 46079 | AR5: 2026/03/15 | AS5: 328 | AT5: P3A1 | AU5: 26 | AV5: e519a11ebf634ab69b0a4744a60039a5 | AW5: 26
A6: QCO | B6: 27 | C6: TRX TRL VST 5L | D6: S2615BA1306U-M | E6: TRX TRL VST 5L | F6: KC5015-WONDER ALUMINA S25-FW26 | G6: P3A1 | H6: 2026 | I6: W06 | J6: 226 | K6: 27 | L6: 167 | M6: P3A1 | N6: LINE09 | O6: AD-ADI-B118 | P6: Main Order | R6: ADIB291 | S6: RGL | T6: 002 | U6: 002 | V6: P_ADI-B118_2_ADIB291RGL002002_01 | W6: Fully Scheduled | X6: P3A1-2512-000000175 | Y6: 2025/12/01 | Z6: 2026/01/31 | AA6: 94.56 | AB6: 20260319 | AC6: 134 | AD6: Week 11 | AE6: 2026-11 | AF6: 22190864 | AG6: 27 | AH6: Week 10 | AI6: 68 | AJ6: 2026/04/15 | AK6: 20260225 | AL6: 20260225 | AM6: 68 | AN6: 2861 | AO6: 46053.776 | AP6: 46078 | AQ6: 46078 | AR6: 2026/04/15 | AS6: 68 | AT6: P3A1 | AU6: 27 | AV6: e519a11ebf634ab69b0a4744a60039a5 | AW6: 27
A7: QCO | B7: 30 | C7: TRX TRL VST 5L | D7: S2615BA1306U-M | E7: TRX TRL VST 5L | F7: KC5015-WONDER ALUMINA S25-FW26 | G7: P3A1 | H7: 2026 | I7: W06 | J7: 729 | K7: 30 | L7: 168 | M7: P3A1 | N7: LINE09 | O7: AD-ADI-B142 | P7: Main Order | R7: ADIB291 | S7: RGL | T7: 002 | U7: 002 | V7: P_ADI-B142_1_ADIB291RGL002002_01 | W7: Not Scheduled | Y7: 2025/12/15 | Z7: 2026/01/31 | AA7: 87.13 | AB7: 20260319 | AC7: 135 | AD7: Week 11 | AE7: 2026-11 | AF7: 22190864 | AG7: 30 | AH7: Week 10 | AI7: 264 | AJ7: 2026/03/31 | AK7: 20260313 | AL7: 20260314 | AM7: 264 | AN7: 3364 | AO7: 46053.814 | AP7: 46094 | AQ7: 46095 | AR7: 2026/03/31 | AS7: 264 | AT7: P3A1 | AU7: 30 | AV7: e519a11ebf634ab69b0a4744a60039a5 | AW7: 30
A8: QCO | B8: 32 | C8: TRX TRL VST 5L | D8: S2615BA1306U-M | E8: TRX TRL VST 5L | F8: KC5015-WONDER ALUMINA S25-FW26 | G8: P3A1 | H8: 2026 | I8: W06 | J8: 822 | K8: 32 | L8: 171 | M8: P3A1 | N8: LINE09 | O8: AD-ADI-B143 | P8: Main Order | R8: ADIB291 | S8: RGL | T8: 002 | U8: 002 | V8: P_ADI-B143_1_ADIB291RGL002002_01 | W8: Not Scheduled | Y8: 2025/12/15 | Z8: 2026/01/31 | AA8: 23.04 | AB8: 20260319 | AC8: 136 | AD8: Week 11 | AE8: 2026-11 | AF8: 22190864 | AG8: 32 | AH8: Week 10 | AI8: 43 | AJ8: 2026/04/15 | AK8: 20260314 | AL8: 20260314 | AM8: 43 | AN8: 3457 | AO8: 46053.815 | AP8: 46095 | AQ8: 46095 | AR8: 2026/04/15 | AS8: 43 | AT8: P3A1 | AU8: 32 | AV8: e519a11ebf634ab69b0a4744a60039a5 | AW8: 32
A9: QCO | B9: 36 | C9: TRX TRL VST 5L | D9: S2615BA1306U-M | E9: TRX TRL VST 5L | F9: KC5015-WONDER ALUMINA S25-FW26 | G9: P3A1 | H9: 2026 | I9: W06 | J9: 904 | K9: 36 | L9: 172 | M9: P3A1 | N9: 3 | O9: AD-ADI-B208 | P9: Main Order | R9: ADIB291 | S9: RGL | T9: 002 | U9: 002 | V9: P_ADI-B208_1_ADIB291RGL002002_01 | W9: Not Scheduled | Y9: 2026/01/24 | Z9: 2026/01/31 | AA9: 0 | AB9: 20260319 | AC9: 137 | AD9: Week 11 | AE9: 2026-11 | AF9: 22190864 | AG9: 36 | AH9: Week 10 | AI9: 2 | AJ9: 2026/04/20 | AK9: 20260302 | AL9: 20260303 | AM9: 2 | AN9: 3539 | AO9: 46053.816 | AP9: 46083 | AQ9: 46084 | AR9: 2026/04/20 | AS9: 2 | AT9: P3A1 | AU9: 36 | AV9: e519a11ebf634ab69b0a4744a60039a5 | AW9: 36
A10: QCO | B10: 37 | C10: TRX TRL VST 5L | D10: S2615BA1306U-M | E10: TRX TRL VST 5L | F10: KC5015-WONDER ALUMINA S25-FW26 | G10: P3A1 | H10: 2026 | I10: W06 | J10: 910 | K10: 37 | L10: 173 | M10: P3A1 | N10: LINE17 | O10: AD-ADI-B211 | P10: Sample Order | R10: ADIB291 | S10: RGL | T10: 002 | U10: 002 | V10: P_ADI-B211_1_ADIB291RGL002002_01 | W10: Not Scheduled | Y10: 2026/01/24 | Z10: 2026/01/31 | AA10: 0 | AB10: 20260319 | AC10: 138 | AD10: Week 11 | AE10: 2026-11 | AF10: 22190864 | AG10: 37 | AH10: Week 10 | AI10: 1 | AJ10: 2026/04/20 | AK10: 20260225 | AL10: 20260225 | AM10: 1 | AN10: 3545 | AO10: 46053.816 | AP10: 46078 | AQ10: 46078 | AR10: 2026/04/20 | AS10: 1 | AT10: P3A1 | AU10: 37 | AV10: e519a11ebf634ab69b0a4744a60039a5 | AW10: 37
A11: QCO | B11: 38 | C11: TRX TRL VST 5L | D11: S2615BA1306U-M | E11: TRX TRL VST 5L | F11: JY7572-TRACE BROWN S17-FW26 | G11: P3A1 | H11: 2026 | I11: W06 | J11: 1056 | K11: 38 | L11: 175 | M11: P3A1 | N11: LINE09 | O11: AD-ADI-B193 | P11: Main Order | R11: ADIB291 | S11: RGL | T11: 001 | U11: 002 | V11: P_ADI-B193_1_ADIB291RGL001002_01 | W11: Not Scheduled | Y11: 2026/01/10 | Z11: 2026/01/31 | AA11: 0 | AB11: 20260319 | AC11: 139 | AD11: Week 11 | AE11: 2026-11 | AF11: 22190864 | AG11: 38 | AH11: Week 10 | AI11: 278 | AJ11: 2026/04/30 | AK11: 20260411 | AL11: 20260411 | AM11: 278 | AN11: 3691 | AO11: 46053.818 | AP11: 46123 | AQ11: 46123 | AR11: 2026/04/30 | AS11: 278 | AT11: P3A1 | AU11: 38 | AV11: e519a11ebf634ab69b0a4744a60039a5 | AW11: 38
A12: QCO | B12: 45 | C12: TRX TRL VST 5L | D12: S2615BA1306U-M | E12: TRX TRL VST 5L | F12: KC5015-WONDER ALUMINA S25-FW26 | G12: P3A1 | H12: 2026 | I12: W06 | J12: 1169 | K12: 45 | L12: 176 | M12: P3A1 | N12: 2 | O12: AD-ADI-B209 | P12: Main Order | R12: ADIB291 | S12: RGL | T12: 002 | U12: 002 | V12: P_ADI-B209_1_ADIB291RGL002002_01 | W12: Not Scheduled | Y12: 2026/01/24 | Z12: 2026/01/31 | AA12: 0 | AB12: 20260319 | AC12: 140 | AD12: Week 11 | AE12: 2026-11 | AF12: 22190864 | AG12: 45 | AH12: Week 10 | AI12: 490 | AJ12: 2026/05/15 | AK12: 20260318 | AL12: 20260319 | AM12: 490 | AN12: 3804 | AO12: 46053.819 | AP12: 46099 | AQ12: 46100 | AR12: 2026/05/15 | AS12: 490 | AT12: P3A1 | AU12: 45 | AV12: e519a11ebf634ab69b0a4744a60039a5 | AW12: 45
A13: QCO | B13: 46 | C13: TRX TRL VST 5L | D13: S2615BA1306U-M | E13: TRX TRL VST 5L | F13: KC5015-WONDER ALUMINA S25-FW26 | G13: P3A1 | H13: 2026 | I13: W06 | J13: 1387 | K13: 46 | L13: 178 | M13: P3A1 | N13: LINE20 | O13: AD-ADI-B144 | P13: Main Order | R13: ADIB291 | S13: RGL | T13: 002 | U13: 002 | V13: P_ADI-B144_1_ADIB291RGL002002_01 | W13: Not Scheduled | Y13: 2025/12/15 | Z13: 2026/01/31 | AA13: 4.84 | AB13: 20260319 | AC13: 141 | AD13: Week 11 | AE13: 2026-11 | AF13: 22190864 | AG13: 46 | AH13: Week 10 | AI13: 55 | AJ13: 2026/08/07 | AK13: 20260509 | AL13: 20260509 | AM13: 55 | AN13: 4022 | AO13: 46053.822 | AP13: 46151 | AQ13: 46151 | AR13: 2026/08/07 | AS13: 55 | AT13: P3A1 | AU13: 46 | AV13: e519a11ebf634ab69b0a4744a60039a5 | AW13: 46
A14: QCO | B14: 47 | C14: TRX TRL VST 5L | D14: S2615BA1306U-M | E14: TRX TRL VST 5L | F14: KC5015-WONDER ALUMINA S25-FW26 | G14: P3A1 | H14: 2026 | I14: W06 | J14: 1392 | K14: 47 | L14: 180 | M14: P3A1 | N14: 2 | O14: AD-ADI-B210 | P14: Main Order | R14: ADIB291 | S14: RGL | T14: 002 | U14: 002 | V14: P_ADI-B210_1_ADIB291RGL002002_01 | W14: Not Scheduled | Y14: 2026/01/24 | Z14: 2026/01/31 | AA14: 0 | AB14: 20260319 | AC14: 142 | AD14: Week 11 | AE14: 2026-11 | AF14: 22190864 | AG14: 47 | AH14: Week 10 | AI14: 139 | AJ14: 2026/08/07 | AK14: 20260318 | AL14: 20260319 | AM14: 139 | AN14: 4027 | AO14: 46053.822 | AP14: 46099 | AQ14: 46100 | AR14: 2026/08/07 | AS14: 139 | AT14: P3A1 | AU14: 47 | AV14: e519a11ebf634ab69b0a4744a60039a5 | AW14: 47
A15: QCO | B15: 79 | C15: SKATEBOARDING CROSS BODY BAG | D15: S26AS6018 | E15: SKATEBOARDING CROSS BODY BAG | F15: KS6824-BLACK-FW26 | G15: P3A1 | H15: 2026 | I15: W06 | J15: 88 | K15: 79 | L15: 779 | M15: P3A1 | N15: LINE11 | O15: AD-ADI-B154 | P15: Main Order | R15: ADIA993 | S15: RGL | T15: 004 | U15: 002 | V15: P_ADI-B154_1_ADIA993RGL004002_01 | W15: Fully Scheduled | X15: P3A1-2512-000000301 | Y15: 2025/12/20 | Z15: 2026/01/31 | AA15: 5.31 | AB15: 20260316 | AC15: 1 | AD15: Week 11 | AE15: 2026-11 | AF15: 22190864 | AG15: 79 | AH15: Week 10 | AI15: 330 | AJ15: 2026/03/31 | AK15: 20260316 | AL15: 20260317 | AM15: 330 | AN15: 2723 | AO15: 46053.774 | AP15: 46097 | AQ15: 46098 | AR15: 2026/03/31 | AS15: 330 | AT15: P3A1 | AU15: 79 | AV15: e519a11ebf634ab69b0a4744a60039a5 | AW15: 79
A16: QCO | B16: 93 | C16: MER IM HB BAG | D16: S2662LHME225 | E16: MER IM HB BAG | F16: KE6058-BLACK-FW26 | G16: P3A1 | H16: 2026 | I16: W06 | J16: 769 | K16: 93 | L16: 1750 | M16: P3A1 | N16: LINE04 | O16: AD-ADI-B192 | P16: Main Order | R16: ADIB041 | S16: RGL | T16: 002 | U16: 003 | V16: P_ADI-B192_1_ADIB041RGL002003_01 | W16: Not Scheduled | Y16: 2026/01/10 | Z16: 2026/01/31 | AA16: 0.76 | AB16: 20260321 | AC16: 260 | AD16: Week 11 | AE16: 2026-11 | AF16: 22190864 | AG16: 93 | AH16: Week 10 | AI16: 259 | AJ16: 2026/03/31 | AK16: 20260314 | AL16: 20260314 | AM16: 259 | AN16: 3404 | AO16: 46053.814 | AP16: 46095 | AQ16: 46095 | AR16: 2026/03/31 | AS16: 259 | AT16: P3A1 | AU16: 93 | AV16: e519a11ebf634ab69b0a4744a60039a5 | AW16: 93
A17: QCO | B17: 99 | C17: MER IM HB BAG | D17: S2662LHME225 | E17: MER IM HB BAG | F17: KE6058-BLACK-FW26 | G17: P3A1 | H17: 2026 | I17: W06 | J17: 919 | K17: 99 | L17: 1841 | M17: P3A1 | N17: LINE04 | O17: AD-ADI-B156 | P17: Sample Order | R17: ADIB041 | S17: RGL | T17: 002 | U17: 003 | V17: P_ADI-B156_1_ADIB041RGL002003_01 | W17: Not Scheduled | Y17: 2025/12/20 | Z17: 2026/01/31 | AA17: 0.87 | AB17: 20260321 | AC17: 261 | AD17: Week 11 | AE17: 2026-11 | AF17: 22190864 | AG17: 99 | AH17: Week 10 | AI17: 1 | AJ17: 2026/04/28 | AK17: 20260314 | AL17: 20260314 | AM17: 1 | AN17: 3554 | AO17: 46053.816 | AP17: 46095 | AQ17: 46095 | AR17: 2026/04/28 | AS17: 1 | AT17: P3A1 | AU17: 99 | AV17: e519a11ebf634ab69b0a4744a60039a5 | AW17: 99
A18: QCO | B18: 100 | C18: SKATEBOARDING CROSS BODY BAG | D18: S26AS6018 | E18: SKATEBOARDING CROSS BODY BAG | F18: KE5758-TRACE KHAKI F17-SS26 | G18: P3A1 | H18: 2026 | I18: W06 | J18: 922 | K18: 100 | L18: 1844 | M18: P3A1 | N18: LINE11 | O18: AD-ADI-A814 | P18: Main Order | R18: ADIA993 | S18: RGL | T18: 002 | U18: 003 | V18: P_ADI-A814_1_ADIA993RGL002003_01 | W18: Not Scheduled | Y18: 2025/05/31 | Z18: 2026/01/31 | AA18: 92.58 | AB18: 20260316 | AC18: 2 | AD18: Week 11 | AE18: 2026-11 | AF18: 22190864 | AG18: 100 | AH18: Week 10 | AI18: 300 | AJ18: 2026/04/30 | AK18: 20260316 | AL18: 20260316 | AM18: 300 | AN18: 3557 | AO18: 46053.816 | AP18: 46097 | AQ18: 46097 | AR18: 2026/04/30 | AS18: 300 | AT18: P3A1 | AU18: 100 | AV18: e519a11ebf634ab69b0a4744a60039a5 | AW18: 100
A19: QCO | B19: 101 | C19: SKATEBOARDING CROSS BODY BAG | D19: S26AS6018 | E19: SKATEBOARDING CROSS BODY BAG | F19: KE5759-CARBON S18-SS26 | G19: P3A1 | H19: 2026 | I19: W06 | J19: 924 | K19: 101 | L19: 1845 | M19: P3A1 | N19: LINE11 | O19: AD-ADI-A814 | P19: Main Order | R19: ADIA993 | S19: RGL | T19: 001 | U19: 004 | V19: P_ADI-A814_1_ADIA993RGL001004_01 | W19: Not Scheduled | Y19: 2025/05/31 | Z19: 2026/01/31 | AA19: 90.33 | AB19: 20260316 | AC19: 3 | AD19: Week 11 | AE19: 2026-11 | AF19: 22190864 | AG19: 101 | AH19: Week 10 | AI19: 230 | AJ19: 2026/04/30 | AK19: 20260316 | AL19: 20260316 | AM19: 230 | AN19: 3559 | AO19: 46053.816 | AP19: 46097 | AQ19: 46097 | AR19: 2026/04/30 | AS19: 230 | AT19: P3A1 | AU19: 101 | AV19: e519a11ebf634ab69b0a4744a60039a5 | AW19: 101
A20: QCO | B20: 109 | C20: MER IM HB BAG | D20: S2662LHME225 | E20: MER IM HB BAG | F20: KE6058-BLACK-FW26 | G20: P3A1 | H20: 2026 | I20: W06 | J20: 1204 | K20: 109 | L20: 2073 | M20: P3A1 | N20: LINE19 | O20: AD-ADI-B155 | P20: Main Order | R20: ADIB041 | S20: RGL | T20: 002 | U20: 003 | V20: P_ADI-B155_1_ADIB041RGL002003_01 | W20: Not Scheduled | Y20: 2025/12/20 | Z20: 2026/01/31 | AA20: 0.43 | AB20: 20260321 | AC20: 262 | AD20: Week 11 | AE20: 2026-11 | AF20: 22190864 | AG20: 109 | AH20: Week 10 | AI20: 53 | AJ20: 2026/05/23 | AK20: 20260505 | AL20: 20260505 | AM20: 53 | AN20: 3839 | AO20: 46053.82 | AP20: 46147 | AQ20: 46147 | AR20: 2026/05/23 | AS20: 53 | AT20: P3A1 | AU20: 109 | AV20: e519a11ebf634ab69b0a4744a60039a5 | AW20: 109
A21: QCO | B21: 131 | C21: 4-W TROLLEY S | D21: S2615LHTR001HS | E21: 4-W TROLLEY S | F21: KW3604-BLACK-SS26 | G21: P3A1 | H21: 2026 | I21: W06 | J21: 7 | K21: 131 | L21: 671 | M21: P3A1 | N21: LINE13 | O21: AD-ADI-B116 | P21: Main Order | R21: ADIB377 | S21: RGL | T21: 001 | U21: 006 | V21: P_ADI-B116_1_ADIB377RGL001006_03 | W21: Fully Scheduled | X21: P3A1-2512-000000100 | Y21: 2025/11/28 | Z21: 2026/01/31 | AA21: 26.78 | AB21: 20260316 | AC21: 4 | AD21: Week 11 | AE21: 2026-11 | AF21: 22190864 | AG21: 131 | AH21: Week 10 | AI21: 407 | AJ21: 2026/02/28 | AK21: 20260121 | AL21: 20260123 | AM21: 1707 | AN21: 2642 | AO21: 46053.773 | AP21: 46043 | AQ21: 46045 | AR21: 2026/02/28 | AS21: 407 | AT21: P3A1 | AU21: 131 | AV21: e519a11ebf634ab69b0a4744a60039a5 | AW21: 131
A22: QCO | B22: 132 | C22: 4-W TROLLEY S | D22: S2615LHTR001HS | E22: 4-W TROLLEY S | F22: KW3604-BLACK-FW26 | G22: P3A1 | H22: 2026 | I22: W06 | J22: 8 | K22: 132 | L22: 672 | M22: P3A1 | N22: LINE13 | O22: AD-ADI-B116 | P22: Main Order | R22: ADIB377 | S22: RGL | T22: 002 | U22: 006 | V22: P_ADI-B116_1_ADIB377RGL002006_01 | W22: Fully Scheduled | X22: P3A1-2512-000000101 | Y22: 2025/11/28 | Z22: 2026/01/31 | AA22: 18.4 | AB22: 20260316 | AC22: 5 | AD22: Week 11 | AE22: 2026-11 | AF22: 22190864 | AG22: 132 | AH22: Week 10 | AI22: 90 | AJ22: 2026/03/15 | AK22: 20260123 | AL22: 20260123 | AM22: 90 | AN22: 2643 | AO22: 46053.773 | AP22: 46045 | AQ22: 46045 | AR22: 2026/03/15 | AS22: 90 | AT22: P3A1 | AU22: 132 | AV22: e519a11ebf634ab69b0a4744a60039a5 | AW22: 132
A23: QCO | B23: 133 | C23: 4-W TROLLEY S | D23: S2615LHTR001HS | E23: 4-W TROLLEY S | F23: KW3604-BLACK-SS26 | G23: P3A1 | H23: 2026 | I23: W06 | J23: 9 | K23: 133 | L23: 675 | M23: P3A1 | N23: LINE13 | O23: AD-ADI-B116 | P23: Main Order | R23: ADIB377 | S23: RGL | T23: 001 | U23: 006 | V23: P_ADI-B116_1_ADIB377RGL001006_02 | W23: Fully Scheduled | X23: P3A1-2512-000000099 | Y23: 2025/11/28 | Z23: 2026/01/31 | AA23: 24.67 | AB23: 20260316 | AC23: 6 | AD23: Week 11 | AE23: 2026-11 | AF23: 22190864 | AG23: 133 | AH23: Week 10 | AI23: 500 | AJ23: 2026/02/28 | AK23: 20260119 | AL23: 20260121 | AM23: 1707 | AN23: 2644 | AO23: 46053.773 | AP23: 46041 | AQ23: 46043 | AR23: 2026/02/28 | AS23: 500 | AT23: P3A1 | AU23: 133 | AV23: e519a11ebf634ab69b0a4744a60039a5 | AW23: 133
A24: QCO | B24: 134 | C24: 4-W TROLLEY S | D24: S2615LHTR001HS | E24: 4-W TROLLEY S | F24: KW3604-BLACK-FW26 | G24: P3A1 | H24: 2026 | I24: W06 | J24: 15 | K24: 134 | L24: 679 | M24: P3A1 | N24: LINE13 | O24: AD-ADI-B142 | P24: Main Order | R24: ADIB377 | S24: RGL | T24: 002 | U24: 007 | V24: P_ADI-B142_1_ADIB377RGL002007_01 | W24: Fully Scheduled | X24: P3A1-2512-000000279 | Y24: 2025/12/15 | Z24: 2026/01/31 | AA24: 14.2 | AB24: 20260316 | AC24: 7 | AD24: Week 11 | AE24: 2026-11 | AF24: 22190864 | AG24: 134 | AH24: Week 10 | AI24: 133 | AJ24: 2026/03/31 | AK24: 20260307 | AL24: 20260307 | AM24: 133 | AN24: 2650 | AO24: 46053.773 | AP24: 46088 | AQ24: 46088 | AR24: 2026/03/31 | AS24: 133 | AT24: P3A1 | AU24: 134 | AV24: e519a11ebf634ab69b0a4744a60039a5 | AW24: 134
A25: QCO | B25: 135 | C25: 4-W TROLLEY S | D25: S2615LHTR001HS | E25: 4-W TROLLEY S | F25: KW3604-BLACK-FW26 | G25: P3A1 | H25: 2026 | I25: W06 | J25: 16 | K25: 135 | L25: 682 | M25: P3A1 | N25: LINE13 | O25: AD-ADI-B049 | P25: Main Order | R25: ADIB377 | S25: RGL | T25: 002 | U25: 005 | V25: P_ADI-B049_1_ADIB377RGL002005_01 | W25: Fully Scheduled | X25: P3A1-2512-000000097 | Y25: 2025/10/31 | Z25: 2026/01/31 | AA25: 30.95 | AB25: 20260316 | AC25: 8 | AD25: Week 11 | AE25: 2026-11 | AF25: 22190864 | AG25: 135 | AH25: Week 10 | AI25: 800 | AJ25: 2026/03/07 | AK25: 20260304 | AL25: 20260307 | AM25: 2202 | AN25: 2651 | AO25: 46053.773 | AP25: 46085 | AQ25: 46088 | AR25: 2026/03/07 | AS25: 800 | AT25: P3A1 | AU25: 135 | AV25: e519a11ebf634ab69b0a4744a60039a5 | AW25: 135
A26: QCO | B26: 136 | C26: 4-W TROLLEY S | D26: S2615LHTR001HS | E26: 4-W TROLLEY S | F26: KW3604-BLACK-FW26 | G26: P3A1 | H26: 2026 | I26: W06 | J26: 54 | K26: 136 | L26: 747 | M26: P3A1 | N26: LINE13 | O26: AD-ADI-B049 | P26: Main Order | R26: ADIB377 | S26: RGL | T26: 002 | U26: 005 | V26: P_ADI-B049_1_ADIB377RGL002005_03 | W26: Fully Scheduled | X26: P3A1-2601-000000188 | Y26: 2025/10/31 | Z26: 2026/01/31 | AA26: 31.75 | AB26: 20260316 | AC26: 9 | AD26: Week 11 | AE26: 2026-11 | AF26: 22190864 | AG26: 136 | AH26: Week 10 | AI26: 551 | AJ26: 2026/03/07 | AK26: 20260312 | AL26: 20260313 | AM26: 2202 | AN26: 2689 | AO26: 46053.774 | AP26: 46093 | AQ26: 46094 | AR26: 2026/03/07 | AS26: 551 | AT26: P3A1 | AU26: 136 | AV26: e519a11ebf634ab69b0a4744a60039a5 | AW26: 136
A27: QCO | B27: 137 | C27: 4-W TROLLEY S | D27: S2615LHTR001HS | E27: 4-W TROLLEY S | F27: KW3604-BLACK-FW26 | G27: P3A1 | H27: 2026 | I27: W06 | J27: 418 | K27: 137 | L27: 1443 | M27: P3A1 | N27: LINE19 | O27: AD-ADI-B175 | P27: Early Order | R27: ADIB377 | S27: RGL | T27: 002 | U27: 010 | V27: P_ADI-B175_1_ADIB377RGL002010_02 | W27: Not Scheduled | Y27: 2025/12/31 | Z27: 2026/01/31 | AA27: 2.24 | AB27: 20260316 | AC27: 10 | AD27: Week 11 | AE27: 2026-11 | AF27: 22190864 | AG27: 137 | AH27: Week 10 | AI27: 400 | AJ27: 2026/02/28 | AK27: 20260506 | AL27: 20260506 | AM27: 600 | AN27: 3053 | AO27: 46053.81 | AP27: 46148 | AQ27: 46148 | AR27: 2026/02/28 | AS27: 400 | AT27: P3A1 | AU27: 137 | AV27: e519a11ebf634ab69b0a4744a60039a5 | AW27: 137
A28: QCO | B28: 138 | C28: 4-W TROLLEY S | D28: S2615LHTR001HS | E28: 4-W TROLLEY S | F28: KW3604-BLACK-FW26 | G28: P3A1 | H28: 2026 | I28: W06 | J28: 419 | K28: 138 | L28: 1444 | M28: P3A1 | N28: LINE20 | O28: AD-ADI-B175 | P28: Early Order | R28: ADIB377 | S28: RGL | T28: 002 | U28: 010 | V28: P_ADI-B175_1_ADIB377RGL002010_01 | W28: Not Scheduled | Y28: 2025/12/31 | Z28: 2026/01/31 | AA28: 2.24 | AB28: 20260316 | AC28: 11 | AD28: Week 11 | AE28: 2026-11 | AF28: 22190864 | AG28: 138 | AH28: Week 10 | AI28: 200 | AJ28: 2026/02/28 | AK28: 20260508 | AL28: 20260508 | AM28: 600 | AN28: 3054 | AO28: 46053.81 | AP28: 46150 | AQ28: 46150 | AR28: 2026/02/28 | AS28: 200 | AT28: P3A1 | AU28: 138 | AV28: e519a11ebf634ab69b0a4744a60039a5 | AW28: 138
A29: QCO | B29: 139 | C29: 4-W TROLLEY S | D29: S2615LHTR001HS | E29: 4-W TROLLEY S | F29: KW3604-BLACK-FW26 | G29: P3A1 | H29: 2026 | I29: W06 | J29: 426 | K29: 139 | L29: 1457 | M29: P3A1 | N29: LINE13 | O29: AD-ADI-B049 | P29: Main Order | R29: ADIB377 | S29: RGL | T29: 002 | U29: 005 | V29: P_ADI-B049_1_ADIB377RGL002005_04 | W29: Not Scheduled | Y29: 2025/10/31 | Z29: 2026/01/31 | AA29: 26.6 | AB29: 20260316 | AC29: 12 | AD29: Week 11 | AE29: 2026-11 | AF29: 22190864 | AG29: 139 | AH29: Week 10 | AI29: 634 | AJ29: 2026/03/07 | AK29: 20260313 | AL29: 20260316 | AM29: 2202 | AN29: 3061 | AO29: 46053.81 | AP29: 46094 | AQ29: 46097 | AR29: 2026/03/07 | AS29: 634 | AT29: P3A1 | AU29: 139 | AV29: e519a11ebf634ab69b0a4744a60039a5 | AW29: 139
A30: QCO | B30: 140 | C30: 4-W TROLLEY S | D30: S2615LHTR001HS | E30: 4-W TROLLEY S | F30: KW3604-BLACK-SS27 | G30: P3A1 | H30: 2026 | I30: W06 | J30: 462 | K30: 140 | L30: 1649 | M30: P3A1 | N30: LINE17 | O30: AD-ADI-B180 | P30: Sample Order | R30: ADIB377 | S30: RGL | T30: 003 | U30: 001 | V30: P_ADI-B180_1_ADIB377RGL003001_01 | W30: Not Scheduled | Y30: 2026/01/12 | Z30: 2026/01/31 | AA30: 63.31 | AB30: 20260316 | AC30: 13 | AD30: Week 11 | AE30: 2026-11 | AF30: 22190864 | AG30: 140 | AH30: Week 10 | AI30: 3 | AJ30: 2026/03/12 | AK30: 20260227 | AL30: 20260227 | AM30: 3 | AN30: 3097 | AO30: 46053.811 | AP30: 46080 | AQ30: 46080 | AR30: 2026/03/12 | AS30: 3 | AT30: P3A1 | AU30: 140 | AV30: e519a11ebf634ab69b0a4744a60039a5 | AW30: 140
A31: QCO | B31: 141 | C31: 4-W TROLLEY S | D31: S2615LHTR001HS | E31: 4-W TROLLEY S | F31: KW3604-BLACK-FW26 | G31: P3A1 | H31: 2026 | I31: W06 | J31: 827 | K31: 141 | L31: 1785 | M31: P3A1 | N31: LINE13 | O31: AD-ADI-B154 | P31: Main Order | R31: ADIB377 | S31: RGL | T31: 002 | U31: 009 | V31: P_ADI-B154_1_ADIB377RGL002009_01 | W31: Not Scheduled | Y31: 2025/12/20 | Z31: 2026/01/31 | AA31: 8.26 | AB31: 20260316 | AC31: 14 | AD31: Week 11 | AE31: 2026-11 | AF31: 22190864 | AG31: 141 | AH31: Week 10 | AI31: 420 | AJ31: 2026/04/15 | AK31: 20260307 | AL31: 20260309 | AM31: 420 | AN31: 3462 | AO31: 46053.815 | AP31: 46088 | AQ31: 46090 | AR31: 2026/04/15 | AS31: 420 | AT31: P3A1 | AU31: 141 | AV31: e519a11ebf634ab69b0a4744a60039a5 | AW31: 141
A32: QCO | B32: 155 | C32: TRX MT DAYPACK | D32: S2615BA1309U | E32: TRX MT DAYPACK | F32: KE1560-BLACK-FW26 | G32: P3A1 | H32: 2026 | I32: W06 | J32: 420 | K32: 155 | L32: 548 | M32: P3A1 | N32: LINE12 | O32: AD-ADI-B142 | P32: Main Order | R32: ADIB083 | S32: RGL | T32: 005 | U32: 001 | V32: P_ADI-B142_1_ADIB083RGL005001_02 | W32: Not Scheduled | Y32: 2025/12/15 | Z32: 2026/01/31 | AA32: 26.15 | AB32: 20260321 | AC32: 226 | AD32: Week 11 | AE32: 2026-11 | AF32: 22190864 | AG32: 155 | AH32: Week 10 | AI32: 201 | AJ32: 2026/03/06 | AK32: 20260313 | AL32: 20260313 | AM32: 203 | AN32: 3055 | AO32: 46053.81 | AP32: 46094 | AQ32: 46094 | AR32: 2026/03/06 | AS32: 201 | AT32: P3A1 | AU32: 155 | AV32: e519a11ebf634ab69b0a4744a60039a5 | AW32: 155
A33: QCO | B33: 164 | C33: TRX MT DAYPACK | D33: S2615BA1309U | E33: TRX MT DAYPACK | F33: KE1560-BLACK-FW26 | G33: P3A1 | H33: 2026 | I33: W06 | J33: 914 | K33: 164 | L33: 558 | M33: P3A1 | N33: LINE12 | O33: AD-ADI-B143 | P33: Main Order | R33: ADIB083 | S33: RGL | T33: 005 | U33: 001 | V33: P_ADI-B143_1_ADIB083RGL005001_01 | W33: Not Scheduled | Y33: 2025/12/15 | Z33: 2026/01/31 | AA33: 25.12 | AB33: 20260321 | AC33: 227 | AD33: Week 11 | AE33: 2026-11 | AF33: 22190864 | AG33: 164 | AH33: Week 10 | AI33: 106 | AJ33: 2026/04/23 | AK33: 20260313 | AL33: 20260313 | AM33: 106 | AN33: 3549 | AO33: 46053.816 | AP33: 46094 | AQ33: 46094 | AR33: 2026/04/23 | AS33: 106 | AT33: P3A1 | AU33: 164 | AV33: e519a11ebf634ab69b0a4744a60039a5 | AW33: 164
A34: QCO | B34: 167 | C34: TRX MT DAYPACK | D34: S2615BA1309U | E34: TRX MT DAYPACK | F34: KE1560-BLACK-FW26 | G34: P3A1 | H34: 2026 | I34: W06 | J34: 1083 | K34: 167 | L34: 560 | M34: P3A1 | N34: LINE12 | O34: AD-ADI-B143 | P34: Main Order | R34: ADIB083 | S34: RGL | T34: 005 | U34: 001 | V34: P_ADI-B143_2_ADIB083RGL005001_01 | W34: Not Scheduled | Y34: 2025/12/15 | Z34: 2026/01/31 | AA34: 25.13 | AB34: 20260321 | AC34: 228 | AD34: Week 11 | AE34: 2026-11 | AF34: 22190864 | AG34: 167 | AH34: Week 10 | AI34: 548 | AJ34: 2026/05/07 | AK34: 20260313 | AL34: 20260314 | AM34: 548 | AN34: 3718 | AO34: 46053.818 | AP34: 46094 | AQ34: 46095 | AR34: 2026/05/07 | AS34: 548 | AT34: P3A1 | AU34: 167 | AV34: e519a11ebf634ab69b0a4744a60039a5 | AW34: 167
A35: QCO | B35: 170 | C35: TRX MT DAYPACK | D35: S2615BA1309U | E35: TRX MT DAYPACK | F35: KE1560-BLACK-FW26 | G35: P3A1 | H35: 2026 | I35: W06 | J35: 1156 | K35: 170 | L35: 561 | M35: P3A1 | N35: 2 | O35: AD-ADI-B209 | P35: Main Order | R35: ADIB083 | S35: RGL | T35: 005 | U35: 001 | V35: P_ADI-B209_1_ADIB083RGL005001_01 | W35: Not Scheduled | Y35: 2026/01/24 | Z35: 2026/01/31 | AA35: 0 | AB35: 20260321 | AC35: 229 | AD35: Week 11 | AE35: 2026-11 | AF35: 22190864 | AG35: 170 | AH35: Week 10 | AI35: 1016 | AJ35: 2026/05/15 | AK35: 20260316 | AL35: 20260318 | AM35: 1016 | AN35: 3791 | AO35: 46053.819 | AP35: 46097 | AQ35: 46099 | AR35: 2026/05/15 | AS35: 1016 | AT35: P3A1 | AU35: 170 | AV35: e519a11ebf634ab69b0a4744a60039a5 | AW35: 170
A36: QCO | B36: 172 | C36: TRX MT DAYPACK | D36: S2615BA1309U | E36: TRX MT DAYPACK | F36: KC5042-TENT GREEN F16-FW26 | G36: P3A1 | H36: 2026 | I36: W06 | J36: 1269 | K36: 172 | L36: 563 | M36: P3A1 | N36: 2 | O36: AD-ADI-B209 | P36: Main Order | R36: ADIB083 | S36: RGL | T36: 006 | U36: 001 | V36: P_ADI-B209_1_ADIB083RGL006001_01 | W36: Not Scheduled | Y36: 2026/01/24 | Z36: 2026/01/31 | AA36: 0 | AB36: 20260321 | AC36: 230 | AD36: Week 11 | AE36: 2026-11 | AF36: 22190864 | AG36: 172 | AH36: Week 10 | AI36: 1085 | AJ36: 2026/06/07 | AK36: 20260316 | AL36: 20260317 | AM36: 1085 | AN36: 3904 | AO36: 46053.821 | AP36: 46097 | AQ36: 46098 | AR36: 2026/06/07 | AS36: 1085 | AT36: P3A1 | AU36: 172 | AV36: e519a11ebf634ab69b0a4744a60039a5 | AW36: 172
A37: QCO | B37: 173 | C37: TRX MT DAYPACK | D37: S2615BA1309U | E37: TRX MT DAYPACK | F37: KE1560-BLACK-FW26 | G37: P3A1 | H37: 2026 | I37: W06 | J37: 1353 | K37: 173 | L37: 564 | M37: P3A1 | N37: LINE20 | O37: AD-ADI-B144 | P37: Main Order | R37: ADIB083 | S37: RGL | T37: 005 | U37: 001 | V37: P_ADI-B144_1_ADIB083RGL005001_01 | W37: Not Scheduled | Y37: 2025/12/15 | Z37: 2026/01/31 | AA37: 4.32 | AB37: 20260321 | AC37: 231 | AD37: Week 11 | AE37: 2026-11 | AF37: 22190864 | AG37: 173 | AH37: Week 10 | AI37: 268 | AJ37: 2026/07/07 | AK37: 20260509 | AL37: 20260509 | AM37: 268 | AN37: 3988 | AO37: 46053.822 | AP37: 46151 | AQ37: 46151 | AR37: 2026/07/07 | AS37: 268 | AT37: P3A1 | AU37: 173 | AV37: e519a11ebf634ab69b0a4744a60039a5 | AW37: 173
A38: QCO | B38: 174 | C38: TRX MT DAYPACK | D38: S2615BA1309U | E38: TRX MT DAYPACK | F38: KE1560-BLACK-FW26 | G38: P3A1 | H38: 2026 | I38: W06 | J38: 1376 | K38: 174 | L38: 565 | M38: P3A1 | N38: 2 | O38: AD-ADI-B210 | P38: Main Order | R38: ADIB083 | S38: RGL | T38: 005 | U38: 001 | V38: P_ADI-B210_1_ADIB083RGL005001_01 | W38: Not Scheduled | Y38: 2026/01/24 | Z38: 2026/01/31 | AA38: 0 | AB38: 20260321 | AC38: 232 | AD38: Week 11 | AE38: 2026-11 | AF38: 22190864 | AG38: 174 | AH38: Week 10 | AI38: 184 | AJ38: 2026/07/15 | AK38: 20260320 | AL38: 20260321 | AM38: 184 | AN38: 4011 | AO38: 46053.822 | AP38: 46101 | AQ38: 46102 | AR38: 2026/07/15 | AS38: 184 | AT38: P3A1 | AU38: 174 | AV38: e519a11ebf634ab69b0a4744a60039a5 | AW38: 174
... A50: QCO | B50: 352 | C50: WC BAG | D50: F26WCBA006 | E50: WC BAG | F50: KY2807-BLACK-FW26 | G50: P3A1 | H50: 2026 | I50: W06 | J50: 1197 | K50: 352 | L50: 2065 | M50: P3A1 | N50: 1 | O50: AD-ADI-B205 | P50: Main Order | R50: ADIB436 | S50: RGL | T50: 001 | U50: 006 | V50: P_ADI-B205_2_ADIB436RGL001006_01 | W50: Not Scheduled | Y50: 2026/01/21 | Z50: 2026/01/31 | AA50: 0 | AB50: 20260319 | AC50: 148 | AD50: Week 11 | AE50: 2026-11 | AF50: 22190864 | AG50: 352 | AH50: Week 10 | AI50: 66 | AJ50: 2026/05/15 | AK50: 20260305 | AL50: 20260306 | AM50: 66 | AN50: 3832 | AO50: 46053.82 | AP50: 46086 | AQ50: 46087 | AR50: 2026/05/15 | AS50: 66 | AT50: P3A1 | AU50: 352 | AV50: e519a11ebf634ab69b0a4744a60039a5 | AW50: 352
A51: QCO | B51: 493 | C51: MER DNA 3S BP | D51: S2662LHMR390 | E51: MER DNA 3S BP | F51: KF1774-BLACK-SS26 | G51: P3A1 | H51: 2026 | I51: W06 | J51: 1 | K51: 493 | L51: 372 | M51: P3A1 | N51: LINE03 | O51: AD-ADI-B052 | P51: Main Order | R51: ADIB034 | S51: RGL | T51: 001 | U51: 004 | V51: P_ADI-B052_2_ADIB034RGL001004_01 | W51: Fully Scheduled | X51: P3A1-2511-000000247 | Y51: 2025/11/03 | Z51: 2026/01/31 | AA51: 94.81 | AB51: 20260317 | AC51: 43 | AD51: Week 11 | AE51: 2026-11 | AF51: 22190864 | AG51: 493 | AH51: Week 09 | AI51: 917 | AJ51: 2026/02/15 | AK51: 20260204 | AL51: 20260204 | AM51: 917 | AN51: 2636 | AO51: 46053.773 | AP51: 46057 | AQ51: 46057 | AR51: 2026/02/15 | AS51: 917 | AT51: P3A1 | AU51: 493 | AV51: e519a11ebf634ab69b0a4744a60039a5 | AW51: 493
...

Sheet Sheet2
A1: QCOSOURCE | B1: RANKING | C1: STYLENAME | D1: BUYERSTYLECODE | E1: BUYERSTYLENAME | F1: STYLECOLORWAYS | G1: QCOFACTORY | H1: QCOYEAR | I1: QCOWEEKNO | J1: QCORANK | K1: CUSTOMRANKING | L1: PRECUSTOMRANK | M1: FACTORY | N1: LINENO | O1: AONO | P1: ADTYPENAME | Q1: BUYER | R1: STYLECODE | S1: STYLESIZE | T1: STYLECOLORSERIAL | U1: REVNO | V1: PRDPKG | W1: MES_SCHEDULING_STATUS | X1: PACKAGEGROUP | Y1: CONFIRMDATE_FACTORY | Z1: CREATEDATE | AA1: NORMALIZEDPERCENT | AB1: QCOSTARTDATE | AC1: CHANGEQCORANK | AD1: REASON | AE1: PRDWEEK | AF1: PREVIOUSCHANGEBY | AG1: PREVIOUSCHANGEQCORANK | AH1: PREVIOUSREASON | AI1: PLANQTY | AJ1: DELIVERYDATE | AK1: PRDSDAT | AL1: PRDEDAT | AM1: ORDQTY | AN1: QCORANKINGNEW | AO1: LATESTQCOTIME | AP1: AOPRDSDAT | AQ1: AOPRDEDAT | AR1: AODELIVERYDATE | AS1: AOPLANQTY | AT1: CHANGEFACTORY | AU1: CHANGEQCORANKSHOW | AV1: QCOVERSION | AW1: MYROWSEQ | AX1: check
